Workbook

Sheet Fork
B3: ClasicaFork | G3: ClasicaFork | L3: ClasicaFork | Q3: ClasicaFork | V3: ClasicaFork
B4: Tamaño Matriz: 50 Hilos:1 | G4: Tamaño Matriz:50 Hilos:2 | L4: Tamaño Matriz:50 Hilos:4 | Q4: Tamaño Matriz:50 Hilos:8 | V4: Tamaño Matriz:50 Hilos:10
B5: VM Javeriana Ubuntu 4 hilos | C5: Replit 8 hilos | D5: Subsistema de Windows para Linux (Ubuntu) 12 hilos | E5: Subsistema de Windows para Linux (Ubuntu) 16 hilos | G5: VM Javeriana Ubuntu 4 hilos | H5: Replit 8 hilos | I5: Subsistema de Windows para Linux (Ubuntu) 12 hilos | J5: Subsistema de Windows para Linux (Ubuntu) 16 hilos | L5: VM Javeriana Ubuntu 4 hilos | M5: Replit 8 hilos | N5: Subsistema de Windows para Linux (Ubuntu) 12 hilos | O5: Subsistema de Windows para Linux (Ubuntu) 16 hilos | Q5: VM Javeriana Ubuntu 4 hilos | R5: Replit 8 hilos | S5: Subsistema de Windows para Linux (Ubuntu) 12 hilos | T5: Subsistema de Windows para Linux (Ubuntu) 16 hilos | V5: VM Javeriana Ubuntu 4 hilos | W5: Replit 8 hilos | X5: Subsistema de Windows para Linux (Ubuntu) 12 hilos | Y5: Subsistema de Windows para Linux (Ubuntu) 16 hilos
B6: 2249 | C6: 310 | D6: 451 | E6: 1440 | G6: 1115 | H6: 347 | I6: 401 | J6: 955 | L6: 865 | M6: 621 | N6: 471 | O6: 1685 | Q6: 1314 | R6: 4908 | S6: 696 | T6: 2587 | V6: 1082 | W6: 1130 | X6: 814 | Y6: 2341
B7: 1134 | C7: 316 | D7: 428 | E7: 1145 | G7: 949 | H7: 344 | I7: 338 | J7: 1119 | L7: 1208 | M7: 771 | N7: 433 | O7: 1256 | Q7: 1261 | R7: 2956 | S7: 635 | T7: 1911 | V7: 1105 | W7: 1493 | X7: 773 | Y7: 1928
B8: 2508 | C8: 296 | D8: 418 | E8: 2144 | G8: 637 | H8: 311 | I8: 335 | J8: 1729 | L8: 986 | M8: 1451 | N8: 426 | O8: 1749 | Q8: 1069 | R8: 2103 | S8: 627 | T8: 2279 | V8: 1317 | W8: 2027 | X8: 910 | Y8: 2089
B9: 1414 | C9: 307 | D9: 425 | E9: 1416 | G9: 883 | H9: 312 | I9: 342 | J9: 1322 | L9: 1111 | M9: 987 | N9: 425 | O9: 2383 | Q9: 1251 | R9: 995 | S9: 715 | T9: 2242 | V9: 1181 | W9: 1170 | X9: 789 | Y9: 2797
B10: 859 | C10: 357 | D10: 415 | E10: 1015 | G10: 998 | H10: 337 | I10: 429 | J10: 1550 | L10: 1128 | M10: 676 | N10: 467 | O10: 2076 | Q10: 1710 | R10: 850 | S10: 804 | T10: 2258 | V10: 1826 | W10: 1775 | X10: 766 | Y10: 2154
B11: 760 | C11: 326 | D11: 395 | E11: 1815 | G11: 1115 | H11: 362 | I11: 345 | J11: 1548 | L11: 1391 | M11: 644 | N11: 499 | O11: 1323 | Q11: 1059 | R11: 1098 | S11: 813 | T11: 2730 | V11: 1463 | W11: 3405 | X11: 922 | Y11: 2301
B12: 790 | C12: 321 | D12: 406 | E12: 1732 | G12: 1368 | H12: 330 | I12: 345 | J12: 880 | L12: 1436 | M12: 3020 | N12: 424 | O12: 1448 | Q12: 1334 | R12: 1266 | S12: 857 | T12: 2260 | V12: 1743 | W12: 2015 | X12: 1007 | Y12: 1823
B13: 846 | C13: 309 | D13: 391 | E13: 1205 | G13: 736 | H13: 365 | I13: 343 | J13: 1286 | L13: 945 | M13: 819 | N13: 424 | O13: 1868 | Q13: 1459 | R13: 1732 | S13: 847 | T13: 2397 | V13: 1748 | W13: 1632 | X13: 802 | Y13: 2472
B14: 927 | C14: 311 | D14: 396 | E14: 1135 | G14: 1767 | H14: 339 | I14: 342 | J14: 1483 | L14: 671 | M14: 740 | N14: 419 | O14: 1120 | Q14: 1263 | R14: 1453 | S14: 838 | T14: 2341 | V14: 1337 | W14: 1557 | X14: 760 | Y14: 1878
B15: 732 | C15: 325 | D15: 481 | E15: 988 | G15: 576 | H15: 377 | I15: 358 | J15: 1031 | L15: 835 | M15: 533 | N15: 424 | O15: 1894 | Q15: 1007 | R15: 995 | S15: 966 | T15: 2000 | V15: 1172 | W15: 2046 | X15: 763 | Y15: 2543
B16: 789 | C16: 294 | D16: 483 | E16: 1237 | G16: 840 | H16: 381 | I16: 350 | J16: 1207 | L16: 863 | M16: 1611 | N16: 414 | O16: 1439 | Q16: 1052 | R16: 1853 | S16: 781 | T16: 2316 | V16: 2277 | W16: 1094 | X16: 689 | Y16: 2977
B17: 1498 | C17: 309 | D17: 396 | E17: 2089 | G17: 837 | H17: 337 | I17: 416 | J17: 1066 | L17: 682 | M17: 1197 | N17: 438 | O17: 1330 | Q17: 1126 | R17: 1663 | S17: 631 | T17: 3478 | V17: 1289 | W17: 1083 | X17: 698 | Y17: 2057
... B35: 1504 | C35: 298 | D35: 393 | E35: 1700 | G35: 663 | H35: 381 | I35: 336 | J35: 1279 | L35: 700 | M35: 1253 | N35: 439 | O35: 1601 | Q35: 1022 | R35: 875 | S35: 623 | T35: 2037 | V35: 1090 | W35: 940 | X35: 785 | Y35: 1855
A36: Promedio | B36: =AVERAGE(B6:B35) -> 1244.4 | C36: =AVERAGE(C6:C35) -> 320.46667 | D36: =AVERAGE(D6:D35) -> 415.63333 | E36: =AVERAGE(E6:E35) -> 1515.7333 | G36: =AVERAGE(G6:G35) -> 868 | H36: =AVERAGE(H6:H35) -> 351.96667 | I36: =AVERAGE(I6:I35) -> 360.66667 | J36: =AVERAGE(J6:J35) -> 1332.1 | L36: =AVERAGE(L6:L35) -> 966.9 | M36: =AVERAGE(M6:M35) -> 853.8 | N36: =AVERAGE(N6:N35) -> 447.63333 | O36: =AVERAGE(O6:O35) -> 1635.9667 | Q36: =AVERAGE(Q6:Q35) -> 1172.6 | R36: =AVERAGE(R6:R35) -> 1446.2667 | S36: =AVERAGE(S6:S35) -> 697.76667 | T36: =AVERAGE(T6:T35) -> 2715 | V36: =AVERAGE(V6:V35) -> 1305.2667 | W36: =AVERAGE(W6:W35) -> 1439.1333 | X36: =AVERAGE(X6:X35) -> 805.63333 | Y36: =AVERAGE(Y6:Y35) -> 2417.3
B39: ClasicaFork | G39: ClasicaFork | L39: ClasicaFork | Q39: ClasicaFork | V39: ClasicaFork
B40: Tamaño Matriz: 100 Hilos:1 | G40: Tamaño Matriz:100 Hilos:2 | L40: Tamaño Matriz:100 Hilos:4 | Q40: Tamaño Matriz:100 Hilos:8 | V40: Tamaño Matriz:100 Hilos:10
B41: VM Javeriana Ubuntu 4 hilos | C41: Replit 8 hilos | D41: Subsistema de Windows para Linux (Ubuntu) 12 hilos | E41: Subsistema de Windows para Linux (Ubuntu) 16 hilos | G41: VM Javeriana Ubuntu 4 hilos | H41: Replit 8 hilos | I41: Subsistema de Windows para Linux (Ubuntu) 12 hilos | J41: Subsistema de Windows para Linux (Ubuntu) 16 hilos | L41: VM Javeriana Ubuntu 4 hilos | M41: Replit 8 hilos | N41: Subsistema de Windows para Linux (Ubuntu) 12 hilos | O41: Subsistema de Windows para Linux (Ubuntu) 16 hilos | Q41: VM Javeriana Ubuntu 4 hilos | R41: Replit 8 hilos | S41: Subsistema de Windows para Linux (Ubuntu) 12 hilos | T41: Subsistema de Windows para Linux (Ubuntu) 16 hilos | V41: VM Javeriana Ubuntu 4 hilos | W41: Replit 8 hilos | X41: Subsistema de Windows para Linux (Ubuntu) 12 hilos | Y41: Subsistema de Windows para Linux (Ubuntu) 16 hilos
B42: 3966 | C42: 952 | D42: 2202 | E42: 4138 | G42: 3341 | H42: 743 | I42: 1170 | J42: 3050 | L42: 1629 | M42: 704 | N42: 1085 | O42: 2939 | Q42: 3570 | R42: 1018 | S42: 1007 | T42: 4101 | V42: 2738 | W42: 1569 | X42: 998 | Y42: 2116
B43: 4650 | C43: 1214 | D43: 2052 | E43: 3585 | G43: 5059 | H43: 755 | I43: 1182 | J43: 2707 | L43: 1753 | M43: 760 | N43: 1070 | O43: 2101 | Q43: 3096 | R43: 1124 | S43: 977 | T43: 3270 | V43: 2331 | W43: 1938 | X43: 989 | Y43: 2500
B44: 4747 | C44: 947 | D44: 2104 | E44: 4944 | G44: 6675 | H44: 1011 | I44: 1211 | J44: 3437 | L44: 4847 | M44: 703 | N44: 1052 | O44: 2308 | Q44: 3127 | R44: 1303 | S44: 1062 | T44: 3516 | V44: 2315 | W44: 2119 | X44: 1075 | Y44: 2612
B45: 3971 | C45: 1018 | D45: 2024 | E45: 4440 | G45: 2877 | H45: 676 | I45: 1587 | J45: 2439 | L45: 3060 | M45: 709 | N45: 1106 | O45: 3234 | Q45: 3123 | R45: 1064 | S45: 1039 | T45: 4010 | V45: 3053 | W45: 1388 | X45: 924 | Y45: 2962
B46: 4063 | C46: 897 | D46: 1957 | E46: 4200 | G46: 2207 | H46: 634 | I46: 1448 | J46: 3401 | L46: 1828 | M46: 801 | N46: 1061 | O46: 2232 | Q46: 2811 | R46: 1388 | S46: 942 | T46: 4859 | V46: 2953 | W46: 3930 | X46: 1475 | Y46: 2504
B47: 3975 | C47: 1071 | D47: 2033 | E47: 5106 | G47: 2229 | H47: 818 | I47: 1345 | J47: 2791 | L47: 2421 | M47: 792 | N47: 1053 | O47: 2773 | Q47: 2081 | R47: 1132 | S47: 1001 | T47: 2945 | V47: 2499 | W47: 2196 | X47: 1058 | Y47: 3007
B48: 4929 | C48: 881 | D48: 2002 | E48: 3999 | G48: 2323 | H48: 760 | I48: 1704 | J48: 3111 | L48: 2366 | M48: 663 | N48: 981 | O48: 2451 | Q48: 2798 | R48: 15591 | S48: 970 | T48: 2873 | V48: 2086 | W48: 2749 | X48: 973 | Y48: 3166
B49: 4270 | C49: 904 | D49: 2004 | E49: 4393 | G49: 2219 | H49: 765 | I49: 1578 | J49: 4537 | L49: 2046 | M49: 850 | N49: 1045 | O49: 2678 | Q49: 2296 | R49: 1040 | S49: 1109 | T49: 3348 | V49: 2345 | W49: 1874 | X49: 1140 | Y49: 2593
B50: 4231 | C50: 925 | D50: 2058 | E50: 5247 | G50: 2267 | H50: 1541 | I50: 1206 | J50: 3758 | L50: 2312 | M50: 734 | N50: 1030 | O50: 1835 | Q50: 2659 | R50: 879 | S50: 1062 | T50: 2644 | V50: 2378 | W50: 2633 | X50: 1141 | Y50: 2197
B51: 4399 | C51: 967 | D51: 1955 | E51: 3782 | G51: 6106 | H51: 1213 | I51: 1174 | J51: 3545 | L51: 2662 | M51: 718 | N51: 1064 | O51: 2771 | Q51: 2493 | R51: 953 | S51: 1426 | T51: 2346 | V51: 2514 | W51: 3704 | X51: 1208 | Y51: 2671
B52: 10223 | C52: 947 | D52: 1987 | E52: 4718 | G52: 3463 | H52: 767 | I52: 1393 | J52: 2530 | L52: 2846 | M52: 836 | N52: 1121 | O52: 1791 | Q52: 3257 | R52: 886 | S52: 1049 | T52: 2482 | V52: 2987 | W52: 1505 | X52: 978 | Y52: 2712
B53: 10281 | C53: 937 | D53: 2086 | E53: 4637 | G53: 3757 | H53: 858 | I53: 1234 | J53: 2336 | L53: 3167 | M53: 830 | N53: 1160 | O53: 2804 | Q53: 2533 | R53: 1003 | S53: 989 | T53: 2926 | V53: 2787 | W53: 1643 | X53: 1256 | Y53: 2342
... B71: 4013 | C71: 923 | D71: 1958 | E71: 4291 | G71: 3174 | H71: 648 | I71: 1122 | J71: 3297 | L71: 1517 | M71: 733 | N71: 986 | O71: 3045 | Q71: 2662 | R71: 1138 | S71: 941 | T71: 2335 | V71: 2840 | W71: 2345 | X71: 1122 | Y71: 2680
A72: Promedio | B72: =AVERAGE(B42:B71) -> 5867.9667 | C72: =AVERAGE(C42:C71) -> 975.06667 | D72: =AVERAGE(D42:D71) -> 2033.7333 | E72: =AVERAGE(E42:E71) -> 4495.7 | G72: =AVERAGE(G42:G71) -> 3364.7667 | H72: =AVERAGE(H42:H71) -> 881.2 | I72: =AVERAGE(I42:I71) -> 1260.6667 | J72: =AVERAGE(J42:J71) -> 3054.8667 | L72: =AVERAGE(L42:L71) -> 2350.8 | M72: =AVERAGE(M42:M71) -> 770.1 | N72: =AVERAGE(N42:N71) -> 1055.5333 | O72: =AVERAGE(O42:O71) -> 2673.3 | Q72: =AVERAGE(Q42:Q71) -> 2743.4667 | R72: =AVERAGE(R42:R71) -> 2088.9333 | S72: =AVERAGE(S42:S71) -> 1031.8667 | T72: =AVERAGE(T42:T71) -> 2881.6333 | V72: =AVERAGE(V42:V71) -> 2458.3667 | W72: =AVERAGE(W42:W71) -> 2502.8333 | X72: =AVERAGE(X42:X71) -> 1153.7667 | Y72: =AVERAGE(Y42:Y71) -> 2620.8
B75: ClasicaFork | G75: ClasicaFork | L75: ClasicaFork | Q75: ClasicaFork | V75: ClasicaFork
B76: Tamaño Matriz: 500 Hilos:1 | G76: Tamaño Matriz:500 Hilos:2 | L76: Tamaño Matriz:500 Hilos:4 | Q76: Tamaño Matriz:500 Hilos:8 | V76: Tamaño Matriz:500 Hilos:10
B77: VM Javeriana Ubuntu 4 hilos | C77: Replit 8 hilos | D77: Subsistema de Windows para Linux (Ubuntu) 12 hilos | E77: Subsistema de Windows para Linux (Ubuntu) 16 hilos | G77: VM Javeriana Ubuntu 4 hilos | H77: Replit 8 hilos | I77: Subsistema de Windows para Linux (Ubuntu) 12 hilos | J77: Subsistema de Windows para Linux (Ubuntu) 16 hilos | L77: VM Javeriana Ubuntu 4 hilos | M77: Replit 8 hilos | N77: Subsistema de Windows para Linux (Ubuntu) 12 hilos | O77: Subsistema de Windows para Linux (Ubuntu) 16 hilos | Q77: VM Javeriana Ubuntu 4 hilos | R77: Replit 8 hilos | S77: Subsistema de Windows para Linux (Ubuntu) 12 hilos | T77: Subsistema de Windows para Linux (Ubuntu) 16 hilos | V77: VM Javeriana Ubuntu 4 hilos | W77: Replit 8 hilos | X77: Subsistema de Windows para Linux (Ubuntu) 12 hilos | Y77: Subsistema de Windows para Linux (Ubuntu) 16 hilos
B78: 518260 | C78: 128049 | D78: 228726 | E78: 446627 | G78: 252594 | H78: 99869 | I78: 119322 | J78: 250499 | L78: 135309 | M78: 149797 | N78: 79026 | O78: 158633 | Q78: 127369 | R78: 105375 | S78: 48690 | T78: 94595 | V78: 128360 | W78: 94677 | X78: 39876 | Y78: 96409
B79: 488295 | C79: 126031 | D79: 228528 | E79: 426374 | G79: 251215 | H79: 108412 | I79: 122755 | J79: 255505 | L79: 131784 | M79: 99432 | N79: 80565 | O79: 155664 | Q79: 137732 | R79: 94122 | S79: 48100 | T79: 96193 | V79: 126335 | W79: 109140 | X79: 39980 | Y79: 80877
B80: 486314 | C80: 112727 | D80: 227364 | E80: 445573 | G80: 252057 | H80: 97368 | I80: 1153832 | J80: 262192 | L80: 126900 | M80: 170380 | N80: 67011 | O80: 153823 | Q80: 135726 | R80: 183324 | S80: 47293 | T80: 99658 | V80: 132856 | W80: 95118 | X80: 36291 | Y80: 84876
...

Sheet Promedios Fork
B3: PROMEDIOS PARA MATRIZ 50x50 | I3: PROMEDIOS PARA MATRIZ 100x100 | P3: PROMEDIOS PARA MATRIZ 500x500
C4: SISTEMA OPERATIVO | J4: SISTEMA OPERATIVO | Q4: SISTEMA OPERATIVO
B5: # de Hilos | C5: VM Javeriana Ubuntu 4 hilos | D5: Replit 8 hilos | E5: Subsistema de Windows para Linux (Ubuntu) 12 hilos | F5: Subsistema de Windows para Linux (Ubuntu) 16 hilos | I5: # de Hilos | J5: VM Javeriana Ubuntu 4 hilos | K5: Replit 8 hilos | L5: Subsistema de Windows para Linux (Ubuntu) 12 hilos | M5: Subsistema de Windows para Linux (Ubuntu) 16 hilos | P5: # de Hilos | Q5: VM Javeriana Ubuntu 4 hilos | R5: Replit 8 hilos | S5: Subsistema de Windows para Linux (Ubuntu) 12 hilos | T5: Subsistema de Windows para Linux (Ubuntu) 16 hilos
B6: 1 | C6: =Fork!B36 -> 1244.4 | D6: =Fork!C36 -> 320.46667 | E6: =Fork!D36 -> 415.63333 | F6: =Fork!E36 -> 1515.7333 | I6: 1 | J6: =Fork!B72 -> 5867.9667 | K6: =Fork!C72 -> 975.06667 | L6: =Fork!D72 -> 2033.7333 | M6: =Fork!E72 -> 4495.7 | P6: 1 | Q6: =Fork!B108 -> 501042.97 | R6: =Fork!C108 -> 117021.37 | S6: =Fork!D108 -> 229871.3 | T6: =Fork!E108 -> 443143.23
B7: 2 | C7: =Fork!G36 -> 868 | D7: =Fork!H36 -> 351.96667 | E7: =Fork!I36 -> 360.66667 | F7: =Fork!J36 -> 1332.1 | I7: 2 | J7: =Fork!G72 -> 3364.7667 | K7: =Fork!H72 -> 881.2 | L7: =Fork!I72 -> 1260.6667 | M7: =Fork!J72 -> 3054.8667 | P7: 2 | Q7: =Fork!G108 -> 250653.77 | R7: =Fork!H108 -> 110748.93 | S7: =Fork!I108 -> 158720.8 | T7: =Fork!J108 -> 246170.03
B8: 4 | C8: =Fork!L36 -> 966.9 | D8: =Fork!M36 -> 853.8 | E8: =Fork!N36 -> 447.63333 | F8: =Fork!O36 -> 1635.9667 | I8: 4 | J8: =Fork!L72 -> 2350.8 | K8: =Fork!M72 -> 770.1 | L8: =Fork!N72 -> 1055.5333 | M8: =Fork!O72 -> 2673.3 | P8: 4 | Q8: =Fork!L108 -> 130419.63 | R8: =Fork!M108 -> 129553.1 | S8: =Fork!N108 -> 76144.567 | T8: =Fork!O108 -> 147761.43
B9: 8 | C9: =Fork!Q36 -> 1172.6 | D9: =Fork!R36 -> 1446.2667 | E9: =Fork!S36 -> 697.76667 | F9: =Fork!T36 -> 2715 | I9: 8 | J9: =Fork!Q72 -> 2743.4667 | K9: =Fork!R72 -> 2088.9333 | L9: =Fork!S72 -> 1031.8667 | M9: =Fork!T72 -> 2881.6333 | P9: 8 | Q9: =Fork!Q108 -> 132673.13 | R9: =Fork!R108 -> 126029.13 | S9: =Fork!S108 -> 46780.467 | T9: =Fork!T108 -> 97015.667
B10: 10 | C10: =Fork!V36 -> 1305.2667 | D10: =Fork!W36 -> 1439.1333 | E10: =Fork!X36 -> 805.63333 | F10: =Fork!Y36 -> 2417.3 | I10: 10 | J10: =Fork!V72 -> 2458.3667 | K10: =Fork!W72 -> 2502.8333 | L10: =Fork!X72 -> 1153.7667 | M10: =Fork!Y72 -> 2620.8 | P10: 10 | Q10: =Fork!V108 -> 130487 | R10: =Fork!W108 -> 134010.23 | S10: =Fork!X108 -> 39158.833 | T10: =Fork!Y108 -> 83724.567
B13: PROMEDIOS PARA MATRIZ 1000x1000 | I13: PROMEDIOS PARA MATRIZ 1500x1500
C14: SISTEMA OPERATIVO | J14: SISTEMA OPERATIVO
B15: # de Hilos | C15: VM Javeriana Ubuntu 4 hilos | D15: Replit 8 hilos | E15: Subsistema de Windows para Linux (Ubuntu) 12 hilos | F15: Subsistema de Windows para Linux (Ubuntu) 16 hilos | I15: # de Hilos | J15: VM Javeriana Ubuntu 4 hilos | K15: Replit 8 hilos | L15: Subsistema de Windows para Linux (Ubuntu) 12 hilos | M15: Subsistema de Windows para Linux (Ubuntu) 16 hilos
B16: 1 | C16: =Fork!B144 -> 4976830.4 | D16: =Fork!C144 -> 933810.43 | E16: =Fork!D144 -> 2003101.7 | F16: =Fork!E144 -> 4180449.9 | I16: 1 | J16: =Fork!B180 -> 21002910 | K16: =Fork!C180 -> 5172375.3 | L16: =Fork!D180 -> 8489286.3 | M16: =Fork!E180 -> 17842644
B17: 2 | C17: =Fork!G144 -> 2384519.5 | D17: =Fork!H144 -> 935846.17 | E17: =Fork!I144 -> 1098625.6 | F17: =Fork!J144 -> 2340885.9 | I17: 2 | J17: =Fork!G180 -> 10312810 | K17: =Fork!H180 -> 4930737.7 | L17: =Fork!I180 -> 4827584.5 | M17: =Fork!J180 -> 9457510.1
B18: 4 | C18: =Fork!L144 -> 1083383.6 | D18: =Fork!M144 -> 1038730.4 | E18: =Fork!N144 -> 650771.63 | F18: =Fork!O144 -> 1558779.4 | I18: 4 | J18: =Fork!L180 -> 5042021.2 | K18: =Fork!M180 -> 4705963.3 | L18: =Fork!N180 -> 2882152.8 | M18: =Fork!O180 -> 6161716.8
B19: 8 | C19: =Fork!Q144 -> 1127360.4 | D19: =Fork!W144 -> 1087144.6 | E19: =Fork!S144 -> 451495.8 | F19: =Fork!T144 -> 1033402 | I19: 8 | J19: =Fork!Q180 -> 4308623.7 | K19: =Fork!R180 -> 4827072.6 | L19: =Fork!S180 -> 1983089.6 | M19: =Fork!T180 -> 4556697.3
B20: 10 | C20: =Fork!V144 -> 1083518.1 | D20: =Fork!W144 -> 1087144.6 | E20: =Fork!X144 -> 400235.77 | F20: =Fork!Y144 -> 939460 | I20: 10 | J20: =Fork!V180 -> 4555716.2 | K20: =Fork!W180 -> 4872267.1 | L20: =Fork!X180 -> 1951863.9 | M20: =Fork!Y180 -> 4475665.5

Sheet OpenMP
B3: ClasicaOpenMP | G3: ClasicaOpenMP | L3: ClasicaOpenMP | Q3: ClasicaOpenMP | V3: ClasicaOpenMP
B4: Tamaño Matriz: 50 Hilos:1 | G4: Tamaño Matriz:50 Hilos:2 | L4: Tamaño Matriz:50 Hilos:4 | Q4: Tamaño Matriz:50 Hilos:8 | V4: Tamaño Matriz:50 Hilos:10
B5: VM Javeriana Ubuntu 4 hilos | C5: Replit 8 hilos | D5: Subsistema de Windows para Linux (Ubuntu) 12 hilos | E5: Subsistema de Windows para Linux (Ubuntu) 16 hilos | G5: VM Javeriana Ubuntu 4 hilos | H5: Replit 8 hilos | I5: Subsistema de Windows para Linux (Ubuntu) 12 hilos | J5: Subsistema de Windows para Linux (Ubuntu) 16 hilos | L5: VM Javeriana Ubuntu 4 hilos | M5: Replit 8 hilos | N5: Subsistema de Windows para Linux (Ubuntu) 12 hilos | O5: Subsistema de Windows para Linux (Ubuntu) 16 hilos | Q5: VM Javeriana Ubuntu 4 hilos | R5: Replit 8 hilos | S5: Subsistema de Windows para Linux (Ubuntu) 12 hilos | T5: Subsistema de Windows para Linux (Ubuntu) 16 hilos | V5: VM Javeriana Ubuntu 4 hilos | W5: Replit 8 hilos | X5: Subsistema de Windows para Linux (Ubuntu) 12 hilos | Y5: Subsistema de Windows para Linux (Ubuntu) 16 hilos
B6: 558 | C6: 70 | D6: 265 | E6: 334 | G6: 417 | H6: 184 | I6: 989 | J6: 520 | L6: 241 | M6: 9591 | N6: 1033 | O6: 784 | Q6: 438 | R6: 359 | S6: 939 | T6: 1058 | V6: 717 | W6: 369 | X6: 1366 | Y6: 1382
B7: 1241 | C7: 69 | D7: 273 | E7: 332 | G7: 416 | H7: 105 | I7: 1027 | J7: 461 | L7: 226 | M7: 356 | N7: 906 | O7: 805 | Q7: 431 | R7: 2362 | S7: 1011 | T7: 837 | V7: 549 | W7: 377 | X7: 1462 | Y7: 1219
B8: 866 | C8: 69 | D8: 324 | E8: 355 | G8: 339 | H8: 1668 | I8: 389 | J8: 564 | L8: 234 | M8: 193 | N8: 1022 | O8: 620 | Q8: 368 | R8: 647 | S8: 2814 | T8: 1062 | V8: 587 | W8: 409 | X8: 2906 | Y8: 1257
B9: 746 | C9: 71 | D9: 295 | E9: 357 | G9: 347 | H9: 150 | I9: 384 | J9: 649 | L9: 286 | M9: 860 | N9: 941 | O9: 923 | Q9: 559 | R9: 395 | S9: 2059 | T9: 724 | V9: 685 | W9: 378 | X9: 1053 | Y9: 1371
B10: 550 | C10: 94 | D10: 255 | E10: 333 | G10: 350 | H10: 117 | I10: 705 | J10: 520 | L10: 233 | M10: 1889 | N10: 1318 | O10: 603 | Q10: 495 | R10: 880 | S10: 985 | T10: 703 | V10: 625 | W10: 390 | X10: 1191 | Y10: 1131
B11: 926 | C11: 103 | D11: 253 | E11: 333 | G11: 300 | H11: 113 | I11: 3470 | J11: 577 | L11: 5671 | M11: 1796 | N11: 959 | O11: 580 | Q11: 1017 | R11: 311 | S11: 1304 | T11: 845 | V11: 2206 | W11: 403 | X11: 1760 | Y11: 1086
B12: 466 | C12: 69 | D12: 269 | E12: 340 | G12: 336 | H12: 622 | I12: 384 | J12: 457 | L12: 3103 | M12: 2835 | N12: 1531 | O12: 724 | Q12: 2663 | R12: 376 | S12: 1020 | T12: 1316 | V12: 538 | W12: 466 | X12: 1230 | Y12: 1075
B13: 462 | C13: 74 | D13: 253 | E13: 513 | G13: 311 | H13: 809 | I13: 399 | J13: 696 | L13: 308 | M13: 268 | N13: 911 | O13: 757 | Q13: 738 | R13: 410 | S13: 1175 | T13: 1539 | V13: 582 | W13: 361 | X13: 1437 | Y13: 1258
B14: 462 | C14: 75 | D14: 252 | E14: 336 | G14: 285 | H14: 324 | I14: 3395 | J14: 644 | L14: 333 | M14: 181 | N14: 901 | O14: 580 | Q14: 794 | R14: 814 | S14: 1066 | T14: 789 | V14: 651 | W14: 353 | X14: 1401 | Y14: 1398
B15: 460 | C15: 84 | D15: 252 | E15: 336 | G15: 306 | H15: 348 | I15: 300 | J15: 672 | L15: 239 | M15: 154 | N15: 712 | O15: 692 | Q15: 788 | R15: 410 | S15: 3272 | T15: 1409 | V15: 616 | W15: 413 | X15: 5029 | Y15: 1864
B16: 521 | C16: 69 | D16: 254 | E16: 379 | G16: 291 | H16: 468 | I16: 381 | J16: 666 | L16: 235 | M16: 1929 | N16: 926 | O16: 526 | Q16: 669 | R16: 389 | S16: 981 | T16: 1709 | V16: 670 | W16: 413 | X16: 4166 | Y16: 1125
B17: 653 | C17: 70 | D17: 253 | E17: 338 | G17: 309 | H17: 225 | I17: 328 | J17: 785 | L17: 248 | M17: 1541 | N17: 940 | O17: 643 | Q17: 916 | R17: 524 | S17: 3041 | T17: 919 | V17: 627 | W17: 543 | X17: 2145 | Y17: 1063
... B35: 655 | C35: 73 | D35: 251 | E35: 338 | G35: 403 | H35: 134 | I35: 180 | J35: 373 | L35: 234 | M35: 151 | N35: 1449 | O35: 528 | Q35: 475 | R35: 339 | S35: 1181 | T35: 1205 | V35: 685 | W35: 535 | X35: 2835 | Y35: 1202
A36: Promedio | B36: =AVERAGE(B6:B35) -> 574.73333 | C36: =AVERAGE(C6:C35) -> 77.133333 | D36: =AVERAGE(D6:D35) -> 257.93333 | E36: =AVERAGE(E6:E35) -> 346.13333 | G36: =AVERAGE(G6:G35) -> 376.73333 | H36: =AVERAGE(H6:H35) -> 432.6 | I36: 168 | J36: =AVERAGE(J6:J35) -> 577.76667 | L36: =AVERAGE(L6:L35) -> 832.13333 | M36: =AVERAGE(M6:M35) -> 1354 | N36: 229 | O36: =AVERAGE(O6:O35) -> 662.53333 | Q36: =AVERAGE(Q6:Q35) -> 700.7 | R36: =AVERAGE(R6:R35) -> 466.93333 | S36: 448 | T36: =AVERAGE(T6:T35) -> 1169.0333 | V36: =AVERAGE(V6:V35) -> 710.53333 | W36: =AVERAGE(W6:W35) -> 590.16667 | X36: 430 | Y36: =AVERAGE(Y6:Y35) -> 1366.1333
B39: ClasicaOpenMP | G39: ClasicaOpenMP | L39: ClasicaOpenMP | Q39: ClasicaOpenMP | V39: ClasicaOpenMP
B40: Tamaño Matriz: 100 Hilos:1 | G40: Tamaño Matriz:100 Hilos:2 | L40: Tamaño Matriz:100 Hilos:4 | Q40: Tamaño Matriz:100 Hilos:8 | V40: Tamaño Matriz:100 Hilos:10
B41: VM Javeriana Ubuntu 4 hilos | C41: Replit 8 hilos | D41: Subsistema de Windows para Linux (Ubuntu) 12 hilos | E41: Subsistema de Windows para Linux (Ubuntu) 16 hilos | G41: VM Javeriana Ubuntu 4 hilos | H41: Replit 8 hilos | I41: Subsistema de Windows para Linux (Ubuntu) 12 hilos | J41: Subsistema de Windows para Linux (Ubuntu) 16 hilos | L41: VM Javeriana Ubuntu 4 hilos | M41: Replit 8 hilos | N41: Subsistema de Windows para Linux (Ubuntu) 12 hilos | O41: Subsistema de Windows para Linux (Ubuntu) 16 hilos | Q41: VM Javeriana Ubuntu 4 hilos | R41: Replit 8 hilos | S41: Subsistema de Windows para Linux (Ubuntu) 12 hilos | T41: Subsistema de Windows para Linux (Ubuntu) 16 hilos | V41: VM Javeriana Ubuntu 4 hilos | W41: Replit 8 hilos | X41: Subsistema de Windows para Linux (Ubuntu) 12 hilos | Y41: Subsistema de Windows para Linux (Ubuntu) 16 hilos
B42: 3892 | C42: 730 | D42: 2164 | E42: 3699 | G42: 4627 | H42: 383 | I42: 2135 | J42: 2189 | L42: 5023 | M42: 322 | N42: 18817 | O42: 2120 | Q42: 2273 | R42: 1239 | S42: 20755 | T42: 1939 | V42: 1479 | W42: 707 | X42: 689 | Y42: 1828
B43: 3823 | C43: 630 | D43: 2201 | E43: 3406 | G43: 2743 | H43: 376 | I43: 2625 | J43: 1713 | L43: 3422 | M43: 1128 | N43: 19418 | O43: 2046 | Q43: 2116 | R43: 955 | S43: 20212 | T43: 1643 | V43: 1514 | W43: 911 | X43: 653 | Y43: 1786
B44: 3827 | C44: 740 | D44: 2220 | E44: 3191 | G44: 2207 | H44: 407 | I44: 2111 | J44: 1704 | L44: 7470 | M44: 273 | N44: 19801 | O44: 1943 | Q44: 2044 | R44: 680 | S44: 18858 | T44: 2193 | V44: 1476 | W44: 567 | X44: 592 | Y44: 1754
B45: 3854 | C45: 777 | D45: 2149 | E45: 2921 | G45: 1958 | H45: 370 | I45: 2346 | J45: 1733 | L45: 2384 | M45: 4792 | N45: 20017 | O45: 1537 | Q45: 1973 | R45: 1083 | S45: 17825 | T45: 1893 | V45: 1758 | W45: 558 | X45: 672 | Y45: 1743
B46: 3748 | C46: 641 | D46: 2183 | E46: 3166 | G46: 1958 | H46: 346 | I46: 2012 | J46: 2553 | L46: 1103 | M46: 6032 | N46: 16602 | O46: 2436 | Q46: 1698 | R46: 960 | S46: 16636 | T46: 1893 | V46: 2216 | W46: 659 | X46: 629 | Y46: 1633
B47: 3789 | C47: 686 | D47: 2177 | E47: 3308 | G47: 1976 | H47: 458 | I47: 2656 | J47: 2262 | L47: 1128 | M47: 2854 | N47: 2955 | O47: 1779 | Q47: 1678 | R47: 878 | S47: 20027 | T47: 1766 | V47: 1860 | W47: 494 | X47: 717 | Y47: 1639
B48: 4148 | C48: 1672 | D48: 2299 | E48: 3079 | G48: 4198 | H48: 418 | I48: 2377 | J48: 2273 | L48: 1101 | M48: 897 | N48: 8049 | O48: 2056 | Q48: 1269 | R48: 675 | S48: 18020 | T48: 1917 | V48: 1649 | W48: 709 | X48: 652 | Y48: 1736
B49: 4099 | C49: 867 | D49: 2188 | E49: 3057 | G49: 3370 | H49: 395 | I49: 2824 | J49: 2705 | L49: 1176 | M49: 5682 | N49: 13421 | O49: 2235 | Q49: 1707 | R49: 511 | S49: 686 | T49: 1772 | V49: 1575 | W49: 624 | X49: 838 | Y49: 1720
B50: 5589 | C50: 702 | D50: 2201 | E50: 2805 | G50: 2202 | H50: 411 | I50: 2742 | J50: 2367 | L50: 1807 | M50: 4216 | N50: 19373 | O50: 1906 | Q50: 1856 | R50: 506 | S50: 837 | T50: 1744 | V50: 1610 | W50: 567 | X50: 661 | Y50: 2086
B51: 3802 | C51: 560 | D51: 2171 | E51: 2862 | G51: 2388 | H51: 365 | I51: 26767 | J51: 2362 | L51: 1730 | M51: 4402 | N51: 18941 | O51: 2291 | Q51: 1645 | R51: 521 | S51: 769 | T51: 1834 | V51: 1500 | W51: 578 | X51: 621 | Y51: 2019
B52: 3840 | C52: 603 | D52: 2091 | E52: 2948 | G52: 2585 | H52: 480 | I52: 2092 | J52: 2679 | L52: 1096 | M52: 3741 | N52: 718 | O52: 1997 | Q52: 1241 | R52: 433 | S52: 626 | T52: 1705 | V52: 1488 | W52: 556 | X52: 644 | Y52: 2144
B53: 3829 | C53: 593 | D53: 2102 | E53: 2788 | G53: 2041 | H53: 438 | I53: 2394 | J53: 2906 | L53: 1092 | M53: 656 | N53: 687 | O53: 1877 | Q53: 1263 | R53: 519 | S53: 615 | T53: 1967 | V53: 1457 | W53: 785 | X53: 705 | Y53: 1803
... B71: 3746 | C71: 583 | D71: 2033 | E71: 2964 | G71: 2022 | H71: 345 | I71: 1047 | J71: 2619 | L71: 2397 | M71: 1959 | N71: 805 | O71: 1475 | Q71: 1294 | R71: 708 | S71: 761 | T71: 1384 | V71: 1557 | W71: 965 | X71: 659 | Y71: 1587
A72: Promedio | B72: =AVERAGE(B42:B71) -> 4236.0333 | C72: =AVERAGE(C42:C71) -> 680.56667 | D72: 1907 | E72: =AVERAGE(E42:E71) -> 3094.3 | G72: =AVERAGE(G42:G71) -> 2920.7667 | H72: =AVERAGE(H42:H71) -> 459.5 | I72: 1078 | J72: =AVERAGE(J42:J71) -> 2271.0667 | L72: =AVERAGE(L42:L71) -> 1913.5 | M72: =AVERAGE(M42:M71) -> 3501.5 | N72: 674 | O72: =AVERAGE(O42:O71) -> 1904.2333 | Q72: =AVERAGE(Q42:Q71) -> 1657.4667 | R72: =AVERAGE(R42:R71) -> 963.13333 | S72: 707 | T72: =AVERAGE(T42:T71) -> 1791.6667 | V72: =AVERAGE(V42:V71) -> 1717.2667 | W72: =AVERAGE(W42:W71) -> 692.76667 | X72: =AVERAGE(X42:X71) -> 713.4 | Y72: =AVERAGE(Y42:Y71) -> 2043.3667
B75: ClasicaOpenMP | G75: ClasicaOpenMP | L75: ClasicaOpenMP | Q75: ClasicaOpenMP | V75: ClasicaOpenMP
B76: Tamaño Matriz: 500 Hilos:1 | G76: Tamaño Matriz:500 Hilos:2 | L76: Tamaño Matriz:500 Hilos:4 | Q76: Tamaño Matriz:500 Hilos:8 | V76: Tamaño Matriz:500 Hilos:10
B77: VM Javeriana Ubuntu 4 hilos | C77: Replit 8 hilos | D77: Subsistema de Windows para Linux (Ubuntu) 12 hilos | E77: Subsistema de Windows para Linux (Ubuntu) 16 hilos | G77: VM Javeriana Ubuntu 4 hilos | H77: Replit 8 hilos | I77: Subsistema de Windows para Linux (Ubuntu) 12 hilos | J77: Subsistema de Windows para Linux (Ubuntu) 16 hilos | L77: VM Javeriana Ubuntu 4 hilos | M77: Replit 8 hilos | N77: Subsistema de Windows para Linux (Ubuntu) 12 hilos | O77: Subsistema de Windows para Linux (Ubuntu) 16 hilos | Q77: VM Javeriana Ubuntu 4 hilos | R77: Replit 8 hilos | S77: Subsistema de Windows para Linux (Ubuntu) 12 hilos | T77: Subsistema de Windows para Linux (Ubuntu) 16 hilos | V77: VM Javeriana Ubuntu 4 hilos | W77: Replit 8 hilos | X77: Subsistema de Windows para Linux (Ubuntu) 12 hilos | Y77: Subsistema de Windows para Linux (Ubuntu) 16 hilos
B78: 478013 | C78: 118663 | D78: 236268 | E78: 525766 | G78: 268586 | H78: 113065 | I78: 119211 | J78: 307605 | L78: 6964609 | M78: 95601 | N78: 82501 | O78: 165695 | Q78: 7151184 | R78: 170656 | S78: 48179 | T78: 141806 | V78: 6599932 | W78: 122661 | X78: 39959 | Y78: 81097
B79: 496169 | C79: 109103 | D79: 236615 | E79: 584568 | G79: 249357 | H79: 99602 | I79: 119830 | J79: 335648 | L79: 130461 | M79: 165847 | N79: 81749 | O79: 170189 | Q79: 128983 | R79: 98629 | S79: 48187 | T79: 112976 | V79: 123867 | W79: 139899 | X79: 42198 | Y79: 87765
B80: 485555 | C80: 110300 | D80: 230445 | E80: 530780 | G80: 248978 | H80: 152260 | I80: 116263 | J80: 331681 | L80: 124403 | M80: 109916 | N80: 90695 | O80: 172747 | Q80: 153778 | R80: 101089 | S80: 46931 | T80: 111524 | V80: 128904 | W80: 95449 | X80: 38524 | Y80: 88451
...

Sheet Promedios OpenMP
B3: PROMEDIOS PARA MATRIZ 50x50 | I3: PROMEDIOS PARA MATRIZ 100x100 | P3: PROMEDIOS PARA MATRIZ 500x500
C4: SISTEMA OPERATIVO | J4: SISTEMA OPERATIVO | Q4: SISTEMA OPERATIVO
B5: # de Hilos | C5: VM Javeriana Ubuntu 4 hilos | D5: Replit 8 hilos | E5: Subsistema de Windows para Linux (Ubuntu) 12 hilos | F5: Subsistema de Windows para Linux (Ubuntu) 16 hilos | I5: # de Hilos | J5: VM Javeriana Ubuntu 4 hilos | K5: Replit 8 hilos | L5: Subsistema de Windows para Linux (Ubuntu) 12 hilos | M5: Subsistema de Windows para Linux (Ubuntu) 16 hilos | P5: # de Hilos | Q5: VM Javeriana Ubuntu 4 hilos | R5: Replit 8 hilos | S5: Subsistema de Windows para Linux (Ubuntu) 12 hilos | T5: Subsistema de Windows para Linux (Ubuntu) 16 hilos
B6: 1 | C6: =OpenMP!B36 -> 574.73333 | D6: =OpenMP!C36 -> 77.133333 | E6: =OpenMP!D36 -> 257.93333 | F6: =OpenMP!E36 -> 346.13333 | I6: 1 | J6: =OpenMP!B72 -> 4236.0333 | K6: =OpenMP!C72 -> 680.56667 | L6: =OpenMP!D72 -> 1907 | M6: =OpenMP!E72 -> 3094.3 | P6: 1 | Q6: =OpenMP!B108 -> 484101 | R6: =OpenMP!C108 -> 115084.53 | S6: =OpenMP!D108 -> 242046.93 | T6: =OpenMP!E108 -> 599782.03
B7: 2 | C7: =OpenMP!G36 -> 376.73333 | D7: =OpenMP!H36 -> 432.6 | E7: =OpenMP!I36 -> 168 | F7: =OpenMP!J36 -> 577.76667 | I7: 2 | J7: =OpenMP!G72 -> 2920.7667 | K7: =OpenMP!H72 -> 459.5 | L7: =OpenMP!I72 -> 1078 | M7: =OpenMP!J72 -> 2271.0667 | P7: 2 | Q7: =OpenMP!G108 -> 254878.1 | R7: =OpenMP!H108 -> 114101.03 | S7: =OpenMP!I108 -> 122834.13 | T7: =OpenMP!J108 -> 303497.87
B8: 4 | C8: =OpenMP!L36 -> 832.13333 | D8: =OpenMP!M36 -> 1354 | E8: =OpenMP!N36 -> 229 | F8: =OpenMP!O36 -> 662.53333 | I8: 4 | J8: =OpenMP!L72 -> 1913.5 | K8: =OpenMP!M72 -> 3501.5 | L8: =OpenMP!N72 -> 674 | M8: =OpenMP!O72 -> 1904.2333 | P8: 4 | Q8: =OpenMP!L108 -> 357137.07 | R8: =OpenMP!M108 -> 133641.8 | S8: =OpenMP!N108 -> 78625.667 | T8: =OpenMP!O108 -> 188760
B9: 8 | C9: =OpenMP!Q36 -> 700.7 | D9: =OpenMP!R36 -> 466.93333 | E9: =OpenMP!S36 -> 448 | F9: =OpenMP!T36 -> 1169.0333 | I9: 8 | J9: =OpenMP!Q72 -> 1657.4667 | K9: =OpenMP!R72 -> 963.13333 | L9: =OpenMP!S72 -> 707 | M9: =OpenMP!T72 -> 1791.6667 | P9: 8 | Q9: =OpenMP!Q108 -> 362235.6 | R9: =OpenMP!R108 -> 115451.33 | S9: =OpenMP!S108 -> 49512.567 | T9: =OpenMP!T108 -> 109972.9
B10: 10 | C10: =OpenMP!V36 -> 710.53333 | D10: =OpenMP!W36 -> 590.16667 | E10: =OpenMP!X36 -> 430 | F10: =OpenMP!Y36 -> 1366.1333 | I10: 10 | J10: =OpenMP!V72 -> 1717.2667 | K10: =OpenMP!W72 -> 692.76667 | L10: =OpenMP!X72 -> 713.4 | M10: =OpenMP!Y72 -> 2043.3667 | P10: 10 | Q10: =OpenMP!V108 -> 341844 | R10: =OpenMP!W108 -> 122604.6 | S10: =OpenMP!X108 -> 41767.9 | T10: =OpenMP!Y108 -> 85268.333
B13: PROMEDIOS PARA MATRIZ 1000x1000 | I13: PROMEDIOS PARA MATRIZ 1500x1500
C14: SISTEMA OPERATIVO | J14: SISTEMA OPERATIVO
B15: # de Hilos | C15: VM Javeriana Ubuntu 4 hilos | D15: Replit 8 hilos | E15: Subsistema de Windows para Linux (Ubuntu) 12 hilos | F15: Subsistema de Windows para Linux (Ubuntu) 16 hilos | I15: # de Hilos | J15: VM Javeriana Ubuntu 4 hilos | K15: Replit 8 hilos | L15: Subsistema de Windows para Linux (Ubuntu) 12 hilos | M15: Subsistema de Windows para Linux (Ubuntu) 16 hilos
B16: 1 | C16: =OpenMP!B144 -> 4916429.9 | D16: =OpenMP!C144 -> 1002872.2 | E16: =OpenMP!D144 -> 2258262 | F16: =OpenMP!E144 -> 4412261.4 | I16: 1 | J16: =OpenMP!B180 -> 20248774 | K16: =OpenMP!C180 -> 5420694.4 | L16: =OpenMP!D180 -> 8806190.6 | M16: =OpenMP!E180 -> 21492528
B17: 2 | C17: =OpenMP!G144 -> 2440560.1 | D17: =OpenMP!H144 -> 958215.93 | E17: =OpenMP!I144 -> 1227186.4 | F17: =OpenMP!J144 -> 2330266.6 | I17: 2 | J17: =OpenMP!G180 -> 9968618.9 | K17: =OpenMP!H180 -> 4888161.8 | L17: =OpenMP!I180 -> 4849300 | M17: =OpenMP!J180 -> 11311299
B18: 4 | C18: =OpenMP!L144 -> 1073268.6 | D18: =OpenMP!M144 -> 1019348 | E18: =OpenMP!N144 -> 704286.93 | F18: =OpenMP!O144 -> 1597333.7 | I18: 4 | J18: =OpenMP!L180 -> 5080173.5 | K18: =OpenMP!M180 -> 4620711.3 | L18: =OpenMP!N180 -> 2886995.7 | M18: =OpenMP!O180 -> 6688440.6
B19: 8 | C19: =OpenMP!Q144 -> 1067126 | D19: =OpenMP!W144 -> 1058403.3 | E19: =OpenMP!S144 -> 454524.77 | F19: =OpenMP!T144 -> 1120623.5 | I19: 8 | J19: =OpenMP!Q180 -> 4076102.3 | K19: =OpenMP!R180 -> 4802868.8 | L19: =OpenMP!S180 -> 1940096.3 | M19: =OpenMP!T180 -> 4957719
B20: 10 | C20: =OpenMP!V144 -> 1053042.9 | D20: =OpenMP!W144 -> 1058403.3 | E20: =OpenMP!X144 -> 396629.97 | F20: =OpenMP!Y144 -> 1041796.3 | I20: 10 | J20: =OpenMP!V180 -> 4365250 | K20: =OpenMP!W180 -> 4796286.1 | L20: =OpenMP!X180 -> 1796019.9 | M20: =OpenMP!Y180 -> 4913438.4

Sheet Posix
B3: ClasicaPosix | G3: ClasicaPosix | L3: ClasicaPosix | Q3: ClasicaPosix | V3: ClasicaPosix
B4: Tamaño Matriz: 50 Hilos:1 | G4: Tamaño Matriz:50 Hilos:2 | L4: Tamaño Matriz:50 Hilos:4 | Q4: Tamaño Matriz:50 Hilos:8 | V4: Tamaño Matriz:50 Hilos:10
B5: VM Javeriana Ubuntu 4 hilos | C5: Replit 8 hilos | D5: Subsistema de Windows para Linux (Ubuntu) 12 hilos | E5: Subsistema de Windows para Linux (Ubuntu) 16 hilos | G5: VM Javeriana Ubuntu 4 hilos | H5: Replit 8 hilos | I5: Subsistema de Windows para Linux (Ubuntu) 12 hilos | J5: Subsistema de Windows para Linux (Ubuntu) 16 hilos | L5: VM Javeriana Ubuntu 4 hilos | M5: Replit 8 hilos | N5: Subsistema de Windows para Linux (Ubuntu) 12 hilos | O5: Subsistema de Windows para Linux (Ubuntu) 16 hilos | Q5: VM Javeriana Ubuntu 4 hilos | R5: Replit 8 hilos | S5: Subsistema de Windows para Linux (Ubuntu) 12 hilos | T5: Subsistema de Windows para Linux (Ubuntu) 16 hilos | V5: VM Javeriana Ubuntu 4 hilos | W5: Replit 8 hilos | X5: Subsistema de Windows para Linux (Ubuntu) 12 hilos | Y5: Subsistema de Windows para Linux (Ubuntu) 16 hilos
B6: 871 | C6: 24344 | D6: 496 | E6: 17529 | G6: 991 | H6: 1865 | I6: 330 | J6: 1391 | L6: 726 | M6: 1237 | N6: 339 | O6: 1130 | Q6: 512 | R6: 1272 | S6: 513 | T6: 2316 | V6: 599 | W6: 1066 | X6: 643 | Y6: 2560
B7: 1660 | C7: 926 | D7: 427 | E7: 1865 | G7: 549 | H7: 1217 | I7: 313 | J7: 838 | L7: 530 | M7: 2647 | N7: 328 | O7: 698 | Q7: 689 | R7: 1333 | S7: 484 | T7: 1978 | V7: 658 | W7: 1235 | X7: 593 | Y7: 2197
B8: 1039 | C8: 1041 | D8: 450 | E8: 1206 | G8: 562 | H8: 1326 | I8: 309 | J8: 944 | L8: 1106 | M8: 1253 | N8: 312 | O8: 1549 | Q8: 585 | R8: 1318 | S8: 450 | T8: 1991 | V8: 650 | W8: 1169 | X8: 586 | Y8: 1976
B9: 788 | C9: 1139 | D9: 483 | E9: 1050 | G9: 591 | H9: 1298 | I9: 312 | J9: 1075 | L9: 485 | M9: 919 | N9: 304 | O9: 1092 | Q9: 616 | R9: 1175 | S9: 478 | T9: 2030 | V9: 588 | W9: 1180 | X9: 535 | Y9: 2068
B10: 735 | C10: 1064 | D10: 451 | E10: 1566 | G10: 573 | H10: 1046 | I10: 385 | J10: 1004 | L10: 516 | M10: 947 | N10: 334 | O10: 1400 | Q10: 652 | R10: 1340 | S10: 475 | T10: 2382 | V10: 493 | W10: 1163 | X10: 568 | Y10: 2166
B11: 779 | C11: 883 | D11: 442 | E11: 1561 | G11: 538 | H11: 1197 | I11: 317 | J11: 1026 | L11: 962 | M11: 904 | N11: 318 | O11: 1071 | Q11: 729 | R11: 1159 | S11: 471 | T11: 1827 | V11: 1053 | W11: 1265 | X11: 783 | Y11: 1674
B12: 760 | C12: 1101 | D12: 443 | E12: 1535 | G12: 537 | H12: 893 | I12: 308 | J12: 1199 | L12: 530 | M12: 888 | N12: 310 | O12: 1064 | Q12: 887 | R12: 1081 | S12: 497 | T12: 2360 | V12: 966 | W12: 1198 | X12: 626 | Y12: 2272
B13: 868 | C13: 1066 | D13: 453 | E13: 1643 | G13: 453 | H13: 1008 | I13: 312 | J13: 759 | L13: 438 | M13: 1205 | N13: 323 | O13: 1525 | Q13: 622 | R13: 1133 | S13: 567 | T13: 1354 | V13: 743 | W13: 1416 | X13: 592 | Y13: 1991
B14: 824 | C14: 985 | D14: 450 | E14: 1748 | G14: 508 | H14: 842 | I14: 300 | J14: 1098 | L14: 536 | M14: 913 | N14: 320 | O14: 1176 | Q14: 648 | R14: 1203 | S14: 488 | T14: 1985 | V14: 751 | W14: 1140 | X14: 537 | Y14: 2182
B15: 731 | C15: 922 | D15: 434 | E15: 2214 | G15: 627 | H15: 887 | I15: 313 | J15: 1177 | L15: 640 | M15: 1047 | N15: 319 | O15: 1020 | Q15: 598 | R15: 1094 | S15: 483 | T15: 1688 | V15: 718 | W15: 1176 | X15: 548 | Y15: 1703
B16: 1471 | C16: 930 | D16: 473 | E16: 1986 | G16: 454 | H16: 879 | I16: 310 | J16: 987 | L16: 748 | M16: 1084 | N16: 324 | O16: 1161 | Q16: 594 | R16: 1386 | S16: 503 | T16: 1544 | V16: 608 | W16: 1200 | X16: 496 | Y16: 1660
B17: 1022 | C17: 982 | D17: 511 | E17: 1122 | G17: 408 | H17: 808 | I17: 314 | J17: 1134 | L17: 430 | M17: 1035 | N17: 326 | O17: 1175 | Q17: 725 | R17: 1047 | S17: 615 | T17: 2027 | V17: 524 | W17: 1226 | X17: 500 | Y17: 1778
... B35: 753 | C35: 2244 | D35: 401 | E35: 1325 | G35: 568 | H35: 902 | I35: 363 | J35: 703 | L35: 392 | M35: 1249 | N35: 321 | O35: 1150 | Q35: 695 | R35: 1586 | S35: 465 | T35: 1268 | V35: 1218 | W35: 1144 | X35: 658 | Y35: 1902
A36: Promedio | B36: =AVERAGE(B6:B35) -> 1137.0333 | C36: =AVERAGE(C6:C35) -> 1811.3333 | D36: =AVERAGE(D6:D35) -> 437.8 | E36: =AVERAGE(E6:E35) -> 1941.6 | G36: =AVERAGE(G6:G35) -> 607.2 | H36: =AVERAGE(H6:H35) -> 1046.7 | I36: 168 | J36: =AVERAGE(J6:J35) -> 1133.1 | L36: =AVERAGE(L6:L35) -> 588.63333 | M36: =AVERAGE(M6:M35) -> 1447.4 | N36: 229 | O36: =AVERAGE(O6:O35) -> 1217.6667 | Q36: =AVERAGE(Q6:Q35) -> 644.8 | R36: =AVERAGE(R6:R35) -> 1261.6333 | S36: 448 | T36: =AVERAGE(T6:T35) -> 1862.3 | V36: =AVERAGE(V6:V35) -> 671.46667 | W36: =AVERAGE(W6:W35) -> 1182.2667 | X36: 430 | Y36: =AVERAGE(Y6:Y35) -> 1986.6667
B39: ClasicaPosix | G39: ClasicaPosix | L39: ClasicaPosix | Q39: ClasicaPosix | V39: ClasicaPosix
B40: Tamaño Matriz: 100 Hilos:1 | G40: Tamaño Matriz:100 Hilos:2 | L40: Tamaño Matriz:100 Hilos:4 | Q40: Tamaño Matriz:100 Hilos:8 | V40: Tamaño Matriz:100 Hilos:10
B41: VM Javeriana Ubuntu 4 hilos | C41: Replit 8 hilos | D41: Subsistema de Windows para Linux (Ubuntu) 12 hilos | E41: Subsistema de Windows para Linux (Ubuntu) 16 hilos | G41: VM Javeriana Ubuntu 4 hilos | H41: Replit 8 hilos | I41: Subsistema de Windows para Linux (Ubuntu) 12 hilos | J41: Subsistema de Windows para Linux (Ubuntu) 16 hilos | L41: VM Javeriana Ubuntu 4 hilos | M41: Replit 8 hilos | N41: Subsistema de Windows para Linux (Ubuntu) 12 hilos | O41: Subsistema de Windows para Linux (Ubuntu) 16 hilos | Q41: VM Javeriana Ubuntu 4 hilos | R41: Replit 8 hilos | S41: Subsistema de Windows para Linux (Ubuntu) 12 hilos | T41: Subsistema de Windows para Linux (Ubuntu) 16 hilos | V41: VM Javeriana Ubuntu 4 hilos | W41: Replit 8 hilos | X41: Subsistema de Windows para Linux (Ubuntu) 12 hilos | Y41: Subsistema de Windows para Linux (Ubuntu) 16 hilos
B42: 3949 | C42: 1558 | D42: 2101 | E42: 4759 | G42: 5538 | H42: 1284 | I42: 1197 | J42: 2102 | L42: 3136 | M42: 1142 | N42: 915 | O42: 1987 | Q42: 1917 | R42: 2672 | S42: 759 | T42: 1685 | V42: 1446 | W42: 1211 | X42: 979 | Y42: 2098
B43: 3954 | C43: 1706 | D43: 2040 | E43: 3841 | G43: 2587 | H43: 1251 | I43: 1139 | J43: 2989 | L43: 2923 | M43: 1097 | N43: 1006 | O43: 2601 | Q43: 1460 | R43: 1358 | S43: 793 | T43: 1519 | V43: 1411 | W43: 1685 | X43: 805 | Y43: 1689
B44: 3993 | C44: 1748 | D44: 2043 | E44: 4174 | G44: 2378 | H44: 1112 | I44: 1742 | J44: 2240 | L44: 1920 | M44: 1254 | N44: 911 | O44: 1933 | Q44: 1285 | R44: 1284 | S44: 768 | T44: 1541 | V44: 2112 | W44: 1499 | X44: 862 | Y44: 2457
B45: 7262 | C45: 1549 | D45: 1984 | E45: 3839 | G45: 3811 | H45: 1176 | I45: 1231 | J45: 2027 | L45: 1088 | M45: 1025 | N45: 934 | O45: 1946 | Q45: 1802 | R45: 1312 | S45: 770 | T45: 1853 | V45: 2261 | W45: 1446 | X45: 785 | Y45: 2038
B46: 4298 | C46: 1588 | D46: 2051 | E46: 4247 | G46: 5157 | H46: 1213 | I46: 1193 | J46: 2505 | L46: 1680 | M46: 1146 | N46: 943 | O46: 1963 | Q46: 1679 | R46: 1308 | S46: 735 | T46: 1628 | V46: 2147 | W46: 2234 | X46: 1163 | Y46: 1978
B47: 4127 | C47: 1494 | D47: 1989 | E47: 3825 | G47: 2171 | H47: 1154 | I47: 1318 | J47: 2712 | L47: 1974 | M47: 1115 | N47: 920 | O47: 2114 | Q47: 2063 | R47: 2409 | S47: 1126 | T47: 1948 | V47: 1658 | W47: 1673 | X47: 710 | Y47: 1879
B48: 4078 | C48: 1858 | D48: 2046 | E48: 4224 | G48: 2358 | H48: 1263 | I48: 1544 | J48: 2645 | L48: 1470 | M48: 1128 | N48: 899 | O48: 1852 | Q48: 1238 | R48: 2397 | S48: 757 | T48: 1696 | V48: 1472 | W48: 1715 | X48: 1216 | Y48: 2955
B49: 9719 | C49: 1679 | D49: 2036 | E49: 4003 | G49: 6872 | H49: 1280 | I49: 1842 | J49: 2079 | L49: 2288 | M49: 1336 | N49: 899 | O49: 2640 | Q49: 1323 | R49: 1525 | S49: 771 | T49: 2099 | V49: 1533 | W49: 1634 | X49: 693 | Y49: 2316
B50: 5361 | C50: 2486 | D50: 2049 | E50: 3496 | G50: 3081 | H50: 1221 | I50: 1160 | J50: 2793 | L50: 3014 | M50: 1179 | N50: 1071 | O50: 2689 | Q50: 1454 | R50: 1213 | S50: 814 | T50: 1506 | V50: 1554 | W50: 3208 | X50: 677 | Y50: 2372
B51: 4239 | C51: 1445 | D51: 2103 | E51: 3923 | G51: 2450 | H51: 1325 | I51: 1211 | J51: 3161 | L51: 2277 | M51: 1108 | N51: 959 | O51: 2096 | Q51: 1411 | R51: 1186 | S51: 812 | T51: 2153 | V51: 1440 | W51: 1594 | X51: 730 | Y51: 1748
B52: 7938 | C52: 1758 | D52: 1993 | E52: 5051 | G52: 2171 | H52: 1130 | I52: 1171 | J52: 2794 | L52: 1356 | M52: 1064 | N52: 998 | O52: 1951 | Q52: 1264 | R52: 1173 | S52: 758 | T52: 2115 | V52: 1552 | W52: 2105 | X52: 819 | Y52: 1939
B53: 4596 | C53: 1607 | D53: 2051 | E53: 4127 | G53: 5743 | H53: 1222 | I53: 1211 | J53: 2549 | L53: 1304 | M53: 1047 | N53: 950 | O53: 1972 | Q53: 1412 | R53: 1253 | S53: 839 | T53: 1849 | V53: 1656 | W53: 3995 | X53: 795 | Y53: 1901
... B71: 4478 | C71: 2040 | D71: 1998 | E71: 3222 | G71: 2897 | H71: 1283 | I71: 1158 | J71: 3194 | L71: 1234 | M71: 1391 | N71: 903 | O71: 2030 | Q71: 1440 | R71: 1294 | S71: 773 | T71: 1645 | V71: 1569 | W71: 1349 | X71: 755 | Y71: 2040
A72: Promedio | B72: =AVERAGE(B42:B71) -> 7029.1333 | C72: =AVERAGE(C42:C71) -> 1709.8333 | D72: 1907 | E72: =AVERAGE(E42:E71) -> 4089.3 | G72: =AVERAGE(G42:G71) -> 4027.3 | H72: =AVERAGE(H42:H71) -> 1229.3667 | I72: 1078 | J72: =AVERAGE(J42:J71) -> 2588.7667 | L72: =AVERAGE(L42:L71) -> 1761.3 | M72: =AVERAGE(M42:M71) -> 1223.2667 | N72: 674 | O72: =AVERAGE(O42:O71) -> 2207.2333 | Q72: =AVERAGE(Q42:Q71) -> 1444.2667 | R72: =AVERAGE(R42:R71) -> 1577.0667 | S72: 707 | T72: =AVERAGE(T42:T71) -> 1884.4667 | V72: =AVERAGE(V42:V71) -> 1690.7333 | W72: =AVERAGE(W42:W71) -> 1974.8 | X72: =AVERAGE(X42:X71) -> 813.66667 | Y72: =AVERAGE(Y42:Y71) -> 2203.3
B75: ClasicaPosix | G75: ClasicaPosix | L75: ClasicaPosix | Q75: ClasicaPosix | V75: ClasicaPosix
B76: Tamaño Matriz: 500 Hilos:1 | G76: Tamaño Matriz:500 Hilos:2 | L76: Tamaño Matriz:500 Hilos:4 | Q76: Tamaño Matriz:500 Hilos:8 | V76: Tamaño Matriz:500 Hilos:10
B77: VM Javeriana Ubuntu 4 hilos | C77: Replit 8 hilos | D77: Subsistema de Windows para Linux (Ubuntu) 12 hilos | E77: Subsistema de Windows para Linux (Ubuntu) 16 hilos | G77: VM Javeriana Ubuntu 4 hilos | H77: Replit 8 hilos | I77: Subsistema de Windows para Linux (Ubuntu) 12 hilos | J77: Subsistema de Windows para Linux (Ubuntu) 16 hilos | L77: VM Javeriana Ubuntu 4 hilos | M77: Replit 8 hilos | N77: Subsistema de Windows para Linux (Ubuntu) 12 hilos | O77: Subsistema de Windows para Linux (Ubuntu) 16 hilos | Q77: VM Javeriana Ubuntu 4 hilos | R77: Replit 8 hilos | S77: Subsistema de Windows para Linux (Ubuntu) 12 hilos | T77: Subsistema de Windows para Linux (Ubuntu) 16 hilos | V77: VM Javeriana Ubuntu 4 hilos | W77: Replit 8 hilos | X77: Subsistema de Windows para Linux (Ubuntu) 12 hilos | Y77: Subsistema de Windows para Linux (Ubuntu) 16 hilos
B78: 477598 | C78: 112238 | D78: 234501 | E78: 429511 | G78: 248003 | H78: 69880 | I78: 139779 | J78: 226252 | L78: 131311 | M78: 95697 | N78: 87393 | O78: 143990 | Q78: 125032 | R78: 174807 | S78: 49664 | T78: 90527 | V78: 127328 | W78: 180398 | X78: 40481 | Y78: 77943
B79: 489742 | C79: 112398 | D79: 235929 | E79: 410740 | G79: 248251 | H79: 148896 | I79: 120264 | J79: 225373 | L79: 125207 | M79: 174839 | N79: 79130 | O79: 138911 | Q79: 124830 | R79: 108388 | S79: 45144 | T79: 94514 | V79: 129348 | W79: 106060 | X79: 39153 | Y79: 80137
B80: 487460 | C80: 113267 | D80: 232622 | E80: 397001 | G80: 273145 | H80: 93305 | I80: 114269 | J80: 231087 | L80: 126734 | M80: 95759 | N80: 70204 | O80: 140631 | Q80: 131153 | R80: 86520 | S80: 45827 | T80: 94238 | V80: 125350 | W80: 90319 | X80: 39738 | Y80: 83778
...

Sheet Promedios Posix
B3: PROMEDIOS PARA MATRIZ 50x50 | I3: PROMEDIOS PARA MATRIZ 100x100 | P3: PROMEDIOS PARA MATRIZ 500x500
C4: SISTEMA OPERATIVO | J4: SISTEMA OPERATIVO | Q4: SISTEMA OPERATIVO
B5: # de Hilos | C5: VM Javeriana Ubuntu 4 hilos | D5: Replit 8 hilos | E5: Subsistema de Windows para Linux (Ubuntu) 12 hilos | F5: Subsistema de Windows para Linux (Ubuntu) 16 hilos | I5: # de Hilos | J5: VM Javeriana Ubuntu 4 hilos | K5: Replit 8 hilos | L5: Subsistema de Windows para Linux (Ubuntu) 12 hilos | M5: Subsistema de Windows para Linux (Ubuntu) 16 hilos | P5: # de Hilos | Q5: VM Javeriana Ubuntu 4 hilos | R5: Replit 8 hilos | S5: Subsistema de Windows para Linux (Ubuntu) 12 hilos | T5: Subsistema de Windows para Linux (Ubuntu) 16 hilos
B6: 1 | C6: =Posix!B36 -> 1137.0333 | D6: =Posix!C36 -> 1811.3333 | E6: =Posix!D36 -> 437.8 | F6: =Posix!E36 -> 1941.6 | I6: 1 | J6: =Posix!B72 -> 7029.1333 | K6: =Posix!C72 -> 1709.8333 | L6: =Posix!D72 -> 1907 | M6: =Posix!E72 -> 4089.3 | P6: 1 | Q6: =Posix!B108 -> 492496.13 | R6: =Posix!C108 -> 114393.7 | S6: =Posix!D108 -> 231003 | T6: =Posix!E108 -> 395578.33
B7: 2 | C7: =Posix!G36 -> 607.2 | D7: =Posix!H36 -> 1046.7 | E7: =Posix!I36 -> 168 | F7: =Posix!J36 -> 1133.1 | I7: 2 | J7: =Posix!G72 -> 4027.3 | K7: =Posix!H72 -> 1229.3667 | L7: =Posix!I72 -> 1078 | M7: =Posix!J72 -> 2588.7667 | P7: 2 | Q7: =Posix!G108 -> 253957.7 | R7: =Posix!H108 -> 109309 | S7: =Posix!I108 -> 122967.5 | T7: =Posix!J108 -> 161960.47
B8: 4 | C8: =Posix!L36 -> 588.63333 | D8: =Posix!M36 -> 1447.4 | E8: =Posix!N36 -> 229 | F8: =Posix!O36 -> 1217.6667 | I8: 4 | J8: =Posix!L72 -> 1761.3 | K8: =Posix!M72 -> 1223.2667 | L8: =Posix!N72 -> 674 | M8: =Posix!O72 -> 2207.2333 | P8: 4 | Q8: =Posix!L108 -> 129507.53 | R8: =Posix!M108 -> 114348.33 | S8: =Posix!N108 -> 77034.1 | T8: =Posix!O108 -> 139152.87
B9: 8 | C9: =Posix!Q36 -> 644.8 | D9: =Posix!R36 -> 1261.6333 | E9: =Posix!S36 -> 448 | F9: =Posix!T36 -> 1862.3 | I9: 8 | J9: =Posix!Q72 -> 1444.2667 | K9: =Posix!R72 -> 1577.0667 | L9: =Posix!S72 -> 707 | M9: =Posix!T72 -> 1884.4667 | P9: 8 | Q9: =Posix!Q108 -> 125072.57 | R9: =Posix!R108 -> 120554.93 | S9: =Posix!S108 -> 47523.233 | T9: =Posix!T108 -> 91218.1
B10: 10 | C10: =Posix!V36 -> 671.46667 | D10: =Posix!W36 -> 1182.2667 | E10: =Posix!X36 -> 430 | F10: =Posix!Y36 -> 1986.6667 | I10: 10 | J10: =Posix!V72 -> 1690.7333 | K10: =Posix!W72 -> 1974.8 | L10: =Posix!X72 -> 813.66667 | M10: =Posix!Y72 -> 2203.3 | P10: 10 | Q10: =Posix!V108 -> 127562.77 | R10: =Posix!W108 -> 131966.13 | S10: =Posix!X108 -> 39510.6 | T10: =Posix!Y108 -> 78180.567
B13: PROMEDIOS PARA MATRIZ 1000x1000 | I13: PROMEDIOS PARA MATRIZ 1500x1500
C14: SISTEMA OPERATIVO | J14: SISTEMA OPERATIVO
B15: # de Hilos | C15: VM Javeriana Ubuntu 4 hilos | D15: Replit 8 hilos | E15: Subsistema de Windows para Linux (Ubuntu) 12 hilos | F15: Subsistema de Windows para Linux (Ubuntu) 16 hilos | I15: # de Hilos | J15: VM Javeriana Ubuntu 4 hilos | K15: Replit 8 hilos | L15: Subsistema de Windows para Linux (Ubuntu) 12 hilos | M15: Subsistema de Windows para Linux (Ubuntu) 16 hilos
B16: 1 | C16: =Posix!B144 -> 4966478.6 | D16: =Posix!C144 -> 933697.57 | E16: =Posix!D144 -> 1991854.5 | F16: =Posix!E144 -> 3856719 | I16: 1 | J16: =Posix!B180 -> 21374005 | K16: =Posix!C180 -> 5042656.3 | L16: =Posix!D180 -> 8612529.7 | M16: =Posix!E180 -> 18041016
B17: 2 | C17: =Posix!G144 -> 2422897.3 | D17: =Posix!H144 -> 920751.43 | E17: =Posix!I144 -> 1084408.6 | F17: =Posix!J144 -> 2147555.2 | I17: 2 | J17: =Posix!G180 -> 10246799 | K17: =Posix!H180 -> 4607654.7 | L17: =Posix!I180 -> 4943792.3 | M17: =Posix!J180 -> 9663883.4
B18: 4 | C18: =Posix!L144 -> 1100681.2 | D18: =Posix!M144 -> 995521.73 | E18: =Posix!N144 -> 679094.43 | F18: =Posix!O144 -> 1378772.2 | I18: 4 | J18: =Posix!L180 -> 5265513.9 | K18: =Posix!M180 -> 4610709.5 | L18: =Posix!N180 -> 2903714.2 | M18: =Posix!O180 -> 6308605.2
B19: 8 | C19: =Posix!Q144 -> 1066073.6 | D19: =Posix!W144 -> 1067881.6 | E19: =Posix!S144 -> 446858.97 | F19: =Posix!T144 -> 934070.4 | I19: 8 | J19: =Posix!Q180 -> 4128583.6 | K19: =Posix!R180 -> 4762460.6 | L19: =Posix!S180 -> 2026874.8 | M19: =Posix!T180 -> 4580479.2
B20: 10 | C20: =Posix!V144 -> 1067517.3 | D20: =Posix!W144 -> 1067881.6 | E20: =Posix!X144 -> 401744.87 | F20: =Posix!Y144 -> 843160.3 | I20: 10 | J20: =Posix!V180 -> 4422448.1 | K20: =Posix!W180 -> 4807465 | L20: =Posix!X180 -> 1941274.8 | M20: =Posix!Y180 -> 4524992.3

Sheet FilasOpenMP
B3: filasOpenMP | G3: filasOpenMP | L3: filasOpenMP | Q3: filasOpenMP | V3: filasOpenMP
B4: Tamaño Matriz: 50 Hilos:1 | G4: Tamaño Matriz:50 Hilos:2 | L4: Tamaño Matriz:50 Hilos:4 | Q4: Tamaño Matriz:50 Hilos:8 | V4: Tamaño Matriz:50 Hilos:10
B5: VM Javeriana Ubuntu 4 hilos | C5: Replit 8 hilos | D5: Subsistema de Windows para Linux (Ubuntu) 12 hilos | E5: Subsistema de Windows para Linux (Ubuntu) 16 hilos | G5: VM Javeriana Ubuntu 4 hilos | H5: Replit 8 hilos | I5: Subsistema de Windows para Linux (Ubuntu) 12 hilos | J5: Subsistema de Windows para Linux (Ubuntu) 16 hilos | L5: VM Javeriana Ubuntu 4 hilos | M5: Replit 8 hilos | N5: Subsistema de Windows para Linux (Ubuntu) 12 hilos | O5: Subsistema de Windows para Linux (Ubuntu) 16 hilos | Q5: VM Javeriana Ubuntu 4 hilos | R5: Replit 8 hilos | S5: Subsistema de Windows para Linux (Ubuntu) 12 hilos | T5: Subsistema de Windows para Linux (Ubuntu) 16 hilos | V5: VM Javeriana Ubuntu 4 hilos | W5: Replit 8 hilos | X5: Subsistema de Windows para Linux (Ubuntu) 12 hilos | Y5: Subsistema de Windows para Linux (Ubuntu) 16 hilos
B6: 690 | C6: 111 | D6: 241 | E6: 1190 | G6: 696 | H6: 172 | I6: 317 | J6: 1471 | L6: 1389 | M6: 11588 | N6: 747 | O6: 2068 | Q6: 826 | R6: 444 | S6: 2687 | T6: 2852 | V6: 985 | W6: 463 | X6: 3088 | Y6: 2956
B7: 1165 | C7: 145 | D7: 266 | E7: 449 | G7: 610 | H7: 8536 | I7: 370 | J7: 2133 | L7: 1054 | M7: 5782 | N7: 2423 | O7: 3701 | Q7: 795 | R7: 578 | S7: 1731 | T7: 2369 | V7: 797 | W7: 594 | X7: 1280 | Y7: 2665
B8: 1025 | C8: 153 | D8: 241 | E8: 435 | G8: 609 | H8: 188 | I8: 3056 | J8: 1392 | L8: 807 | M8: 83560 | N8: 2529 | O8: 2196 | Q8: 839 | R8: 1187 | S8: 2301 | T8: 2806 | V8: 816 | W8: 470 | X8: 1376 | Y8: 3484
B9: 661 | C9: 157 | D9: 268 | E9: 641 | G9: 1054 | H9: 11629 | I9: 369 | J9: 1457 | L9: 6082 | M9: 5674 | N9: 698 | O9: 1840 | Q9: 6710 | R9: 537 | S9: 1737 | T9: 2406 | V9: 924 | W9: 657 | X9: 1028 | Y9: 6293
B10: 509 | C10: 151 | D10: 266 | E10: 434 | G10: 6118 | H10: 162 | I10: 382 | J10: 1168 | L10: 5611 | M10: 9572 | N10: 670 | O10: 2939 | Q10: 4150 | R10: 493 | S10: 1745 | T10: 2864 | V10: 907 | W10: 483 | X10: 1454 | Y10: 3043
B11: 510 | C11: 149 | D11: 264 | E11: 413 | G11: 741 | H11: 8268 | I11: 3410 | J11: 1496 | L11: 4668 | M11: 6450 | N11: 791 | O11: 3873 | Q11: 7139 | R11: 25204 | S11: 1297 | T11: 5713 | V11: 864 | W11: 631 | X11: 4064 | Y11: 3071
B12: 525 | C12: 147 | D12: 298 | E12: 395 | G12: 1577 | H12: 147 | I12: 338 | J12: 1180 | L12: 7923 | M12: 205 | N12: 693 | O12: 2166 | Q12: 792 | R12: 12328 | S12: 2459 | T12: 2822 | V12: 5782 | W12: 463 | X12: 2754 | Y12: 6791
B13: 509 | C13: 170 | D13: 263 | E13: 390 | G13: 1698 | H13: 667 | I13: 2640 | J13: 1682 | L13: 657 | M13: 435 | N13: 711 | O13: 2255 | Q13: 722 | R13: 867 | S13: 983 | T13: 3318 | V13: 821 | W13: 558 | X13: 3793 | Y13: 3200
B14: 548 | C14: 86 | D14: 264 | E14: 418 | G14: 1287 | H14: 149 | I14: 372 | J14: 1522 | L14: 650 | M14: 539 | N14: 1129 | O14: 2135 | Q14: 849 | R14: 3050 | S14: 1347 | T14: 2909 | V14: 855 | W14: 706 | X14: 1021 | Y14: 6032
B15: 533 | C15: 80 | D15: 263 | E15: 386 | G15: 1669 | H15: 157 | I15: 3145 | J15: 1441 | L15: 631 | M15: 4021 | N15: 1071 | O15: 2159 | Q15: 788 | R15: 3189 | S15: 1305 | T15: 3253 | V15: 907 | W15: 620 | X15: 1474 | Y15: 3083
B16: 538 | C16: 149 | D16: 265 | E16: 408 | G16: 1170 | H16: 1445 | I16: 407 | J16: 1137 | L16: 790 | M16: 189 | N16: 1179 | O16: 3536 | Q16: 1063 | R16: 493 | S16: 1462 | T16: 2588 | V16: 850 | W16: 562 | X16: 1037 | Y16: 3118
B17: 539 | C17: 153 | D17: 264 | E17: 522 | G17: 1244 | H17: 755 | I17: 381 | J17: 1421 | L17: 674 | M17: 1866 | N17: 848 | O17: 1989 | Q17: 988 | R17: 861 | S17: 1485 | T17: 3057 | V17: 1201 | W17: 1015 | X17: 1045 | Y17: 3276
... B35: 509 | C35: 149 | D35: 240 | E35: 382 | G35: 1028 | H35: 169 | I35: 387 | J35: 1376 | L35: 6837 | M35: 13137 | N35: 758 | O35: 5247 | Q35: 6906 | R35: 3247 | S35: 1632 | T35: 2510 | V35: 6586 | W35: 580 | X35: 1178 | Y35: 3249
A36: Promedio | B36: =AVERAGE(B6:B35) -> 663.96667 | C36: =AVERAGE(C6:C35) -> 141.06667 | D36: =AVERAGE(D6:D35) -> 256.33333 | E36: =AVERAGE(E6:E35) -> 457.06667 | G36: =AVERAGE(G6:G35) -> 1792.3333 | H36: =AVERAGE(H6:H35) -> 1776.8 | I36: 168 | J36: =AVERAGE(J6:J35) -> 1481.8 | L36: =AVERAGE(L6:L35) -> 2572.4667 | M36: =AVERAGE(M6:M35) -> 7505.6333 | N36: 229 | O36: =AVERAGE(O6:O35) -> 2822.5333 | Q36: =AVERAGE(Q6:Q35) -> 2306.6333 | R36: =AVERAGE(R6:R35) -> 3525.7 | S36: 448 | T36: =AVERAGE(T6:T35) -> 3330.4667 | V36: =AVERAGE(V6:V35) -> 2194.8667 | W36: =AVERAGE(W6:W35) -> 1583.5333 | X36: 430 | Y36: =AVERAGE(Y6:Y35) -> 4624.5333
B39: filasOpenMP | G39: filasOpenMP | L39: filasOpenMP | Q39: filasOpenMP | V39: filasOpenMP
B40: Tamaño Matriz: 100 Hilos:1 | G40: Tamaño Matriz:100 Hilos:2 | L40: Tamaño Matriz:100 Hilos:4 | Q40: Tamaño Matriz:100 Hilos:8 | V40: Tamaño Matriz:100 Hilos:10
B41: VM Javeriana Ubuntu 4 hilos | C41: Replit 8 hilos | D41: Subsistema de Windows para Linux (Ubuntu) 12 hilos | E41: Subsistema de Windows para Linux (Ubuntu) 16 hilos | G41: VM Javeriana Ubuntu 4 hilos | H41: Replit 8 hilos | I41: Subsistema de Windows para Linux (Ubuntu) 12 hilos | J41: Subsistema de Windows para Linux (Ubuntu) 16 hilos | L41: VM Javeriana Ubuntu 4 hilos | M41: Replit 8 hilos | N41: Subsistema de Windows para Linux (Ubuntu) 12 hilos | O41: Subsistema de Windows para Linux (Ubuntu) 16 hilos | Q41: VM Javeriana Ubuntu 4 hilos | R41: Replit 8 hilos | S41: Subsistema de Windows para Linux (Ubuntu) 12 hilos | T41: Subsistema de Windows para Linux (Ubuntu) 16 hilos | V41: VM Javeriana Ubuntu 4 hilos | W41: Replit 8 hilos | X41: Subsistema de Windows para Linux (Ubuntu) 12 hilos | Y41: Subsistema de Windows para Linux (Ubuntu) 16 hilos
B42: 4698 | C42: 1299 | D42: 2131 | E42: 3351 | G42: 11688 | H42: 412 | I42: 2304 | J42: 8485 | L42: 9946 | M42: 31900 | N42: 4835 | O42: 32415 | Q42: 59488 | R42: 62560 | S42: 6670 | T42: 13305 | V42: 4530 | W42: 3451 | X42: 7147 | Y42: 14176
B43: 4570 | C43: 1343 | D43: 2086 | E43: 4029 | G43: 9232 | H43: 622 | I43: 1961 | J43: 8600 | L43: 55188 | M43: 3575 | N43: 5706 | O43: 30012 | Q43: 53327 | R43: 17041 | S43: 8279 | T43: 12445 | V43: 5060 | W43: 1443 | X43: 6522 | Y43: 15458
B44: 4232 | C44: 1185 | D44: 2109 | E44: 3189 | G44: 4215 | H44: 633 | I44: 22248 | J44: 11045 | L44: 4342 | M44: 18702 | N44: 4943 | O44: 27272 | Q44: 7522 | R44: 4839 | S44: 6804 | T44: 40440 | V44: 4272 | W44: 1298 | X44: 16777 | Y44: 16415
B45: 4245 | C45: 1253 | D45: 2121 | E45: 3088 | G45: 4050 | H45: 41886 | I45: 2355 | J45: 7775 | L45: 4271 | M45: 8730 | N45: 16983 | O45: 10824 | Q45: 60211 | R45: 8524 | S45: 7967 | T45: 15033 | V45: 8238 | W45: 1438 | X45: 5730 | Y45: 48093
B46: 4362 | C46: 1154 | D46: 2121 | E46: 3469 | G46: 4044 | H46: 849 | I46: 2271 | J46: 8404 | L46: 4329 | M46: 436 | N46: 5469 | O46: 10771 | Q46: 5164 | R46: 4147 | S46: 8842 | T46: 42480 | V46: 52108 | W46: 1405 | X46: 6459 | Y46: 17128
B47: 5583 | C47: 13323 | D47: 2090 | E47: 2989 | G47: 56455 | H47: 676 | I47: 23264 | J47: 8285 | L47: 6559 | M47: 2036 | N47: 4864 | O47: 30623 | Q47: 5860 | R47: 15630 | S47: 6149 | T47: 43358 | V47: 6072 | W47: 1176 | X47: 6615 | Y47: 16517
B48: 8771 | C48: 1169 | D48: 2137 | E48: 2908 | G48: 13227 | H48: 2562 | I48: 2096 | J48: 9492 | L48: 4833 | M48: 18485 | N48: 4797 | O48: 10422 | Q48: 5286 | R48: 1082 | S48: 6489 | T48: 42856 | V48: 55045 | W48: 1616 | X48: 6540 | Y48: 16320
B49: 7021 | C49: 1177 | D49: 1990 | E49: 3042 | G49: 45219 | H49: 4751 | I49: 2683 | J49: 8937 | L49: 4382 | M49: 7903 | N49: 7184 | O49: 36344 | Q49: 6109 | R49: 2887 | S49: 18158 | T49: 14305 | V49: 46906 | W49: 1502 | X49: 18455 | Y49: 16331
B50: 4994 | C50: 1148 | D50: 2045 | E50: 3142 | G50: 39175 | H50: 9268 | I50: 21298 | J50: 9526 | L50: 4375 | M50: 6443 | N50: 12668 | O50: 41669 | Q50: 5365 | R50: 1107 | S50: 6373 | T50: 12443 | V50: 5180 | W50: 1332 | X50: 5530 | Y50: 14709
B51: 4449 | C51: 1008 | D51: 2034 | E51: 3022 | G51: 6028 | H51: 775 | I51: 2383 | J51: 8388 | L51: 4405 | M51: 5377 | N51: 5870 | O51: 30730 | Q51: 55218 | R51: 6703 | S51: 17484 | T51: 13133 | V51: 4568 | W51: 1064 | X51: 6383 | Y51: 49049
B52: 4379 | C52: 662 | D52: 1894 | E52: 2911 | G52: 8689 | H52: 3595 | I52: 2578 | J52: 8008 | L52: 51900 | M52: 17272 | N52: 4943 | O52: 13070 | Q52: 6813 | R52: 916 | S52: 6385 | T52: 38990 | V52: 56970 | W52: 1038 | X52: 6559 | Y52: 17581
B53: 9249 | C53: 898 | D53: 1965 | E53: 3101 | G53: 4020 | H53: 4292 | I53: 17026 | J53: 9471 | L53: 7000 | M53: 7550 | N53: 4658 | O53: 11104 | Q53: 7352 | R53: 2201 | S53: 5920 | T53: 13628 | V53: 4899 | W53: 1009 | X53: 18093 | Y53: 48532
... B71: 5157 | C71: 940 | D71: 1894 | E71: 3159 | G71: 54487 | H71: 652 | I71: 2491 | J71: 8369 | L71: 4336 | M71: 17106 | N71: 7618 | O71: 12934 | Q71: 6180 | R71: 1104 | S71: 19188 | T71: 13183 | V71: 4495 | W71: 1551 | X71: 7551 | Y71: 49321
A72: Promedio | B72: =AVERAGE(B42:B71) -> 6334.4333 | C72: =AVERAGE(C42:C71) -> 1506.4667 | D72: 1907 | E72: =AVERAGE(E42:E71) -> 3184.3333 | G72: =AVERAGE(G42:G71) -> 27133.733 | H72: =AVERAGE(H42:H71) -> 4336 | I72: 1078 | J72: =AVERAGE(J42:J71) -> 8739.2667 | L72: =AVERAGE(L42:L71) -> 15153.7 | M72: =AVERAGE(M42:M71) -> 8065 | N72: 674 | O72: =AVERAGE(O42:O71) -> 19000.233 | Q72: =AVERAGE(Q42:Q71) -> 19429.467 | R72: =AVERAGE(R42:R71) -> 5557.4667 | S72: 707 | T72: =AVERAGE(T42:T71) -> 23081.433 | V72: =AVERAGE(V42:V71) -> 24563.7 | W72: =AVERAGE(W42:W71) -> 1994 | X72: =AVERAGE(X42:X71) -> 8728.7 | Y72: =AVERAGE(Y42:Y71) -> 25875.9
B75: filasOpenMP | G75: filasOpenMP | L75: filasOpenMP | Q75: filasOpenMP | V75: filasOpenMP
B76: Tamaño Matriz: 500 Hilos:1 | G76: Tamaño Matriz:500 Hilos:2 | L76: Tamaño Matriz:500 Hilos:4 | Q76: Tamaño Matriz:500 Hilos:8 | V76: Tamaño Matriz:500 Hilos:10
B77: VM Javeriana Ubuntu 4 hilos | C77: Replit 8 hilos | D77: Subsistema de Windows para Linux (Ubuntu) 12 hilos | E77: Subsistema de Windows para Linux (Ubuntu) 16 hilos | G77: VM Javeriana Ubuntu 4 hilos | H77: Replit 8 hilos | I77: Subsistema de Windows para Linux (Ubuntu) 12 hilos | J77: Subsistema de Windows para Linux (Ubuntu) 16 hilos | L77: VM Javeriana Ubuntu 4 hilos | M77: Replit 8 hilos | N77: Subsistema de Windows para Linux (Ubuntu) 12 hilos | O77: Subsistema de Windows para Linux (Ubuntu) 16 hilos | Q77: VM Javeriana Ubuntu 4 hilos | R77: Replit 8 hilos | S77: Subsistema de Windows para Linux (Ubuntu) 12 hilos | T77: Subsistema de Windows para Linux (Ubuntu) 16 hilos | V77: VM Javeriana Ubuntu 4 hilos | W77: Replit 8 hilos | X77: Subsistema de Windows para Linux (Ubuntu) 12 hilos | Y77: Subsistema de Windows para Linux (Ubuntu) 16 hilos
B78: 527828 | C78: 128922 | D78: 248085 | E78: 402993 | G78: 521031 | H78: 162582 | I78: 321562 | J78: 1118231 | L78: 6879929 | M78: 138674 | N78: 401397 | O78: 1434722 | Q78: 540340 | R78: 88045 | S78: 524356 | T78: 3281503 | V78: 536241 | W78: 109592 | X78: 542096 | Y78: 5995607
B79: 511297 | C79: 153156 | D79: 243966 | E79: 398860 | G79: 534864 | H79: 141747 | I79: 371024 | J79: 1041156 | L79: 6860571 | M79: 120365 | N79: 373664 | O79: 1751810 | Q79: 5879543 | R79: 160287 | S79: 507362 | T79: 1667951 | V79: 528292 | W79: 150452 | X79: 2201564 | Y79: 1795648
B80: 540376 | C80: 170462 | D80: 253077 | E80: 386500 | G80: 491258 | H80: 115133 | I80: 2294014 | J80: 1054565 | L80: 6807297 | M80: 168035 | N80: 377708 | O80: 4473720 | Q80: 563602 | R80: 122644 | S80: 445277 | T80: 5545645 | V80: 513122 | W80: 108686 | X80: 528342 | Y80: 1767099
...

Sheet Promedios FilasOpenMP
B3: PROMEDIOS PARA MATRIZ 50x50 | I3: PROMEDIOS PARA MATRIZ 100x100 | P3: PROMEDIOS PARA MATRIZ 500x500
C4: SISTEMA OPERATIVO | J4: SISTEMA OPERATIVO | Q4: SISTEMA OPERATIVO
